Workbook

Sheet Resume
A1: Riskfolio-Lib Report
A2: Copyright (c) 2020-2023, Dany Cajas All rights reserved. Redistribution and use in source and binary forms, with or without modification, are permitted provided that the following conditions are met: * Redistributions of source code must retain the above copyright notice, this list of conditions and the following disclaimer. * Redistributions in binary form must reproduce the above copyright notice, this list of conditions and the following disclaimer in the documentation and/or other materials provided with the distribution. * Neither the name of Riskfolio-Lib nor the names of its contributors may be used to endorse or promote products derived from this software without specific prior written permission. THIS SOFTWARE IS PROVIDED BY THE COPYRIGHT HOLDERS AND CONTRIBUTORS "AS IS" AND ANY EXPRESS OR IMPLIED WARRANTIES, INCLUDING, BUT NOT LIMITED TO, THE IMPLIED WARRANTIES OF MERCHANTABILITY AND FITNESS FOR A PARTICULAR PURPOSE ARE DISCLAIMED. IN NO EVENT SHALL THE COPYRIGHT HOLDER OR CONTRIBUTORS BE LIABLE FOR ANY DIRECT, INDIRECT, INCIDENTAL, SPECIAL, EXEMPLARY, OR CONSEQUENTIAL DAMAGES (INCLUDING, BUT NOT LIMITED TO, PROCUREMENT OF SUBSTITUTE GOODS OR SERVICES; LOSS OF USE, DATA, OR PROFITS; OR BUSINESS INTERRUPTION) HOWEVER CAUSED AND ON ANY THEORY OF LIABILITY, WHETHER IN CONTRACT, STRICT LIABILITY, OR TORT (INCLUDING NEGLIGENCE OR OTHERWISE) ARISING IN ANY WAY OUT OF THE USE OF THIS SOFTWARE, EVEN IF ADVISED OF THE POSSIBILITY OF SUCH DAMAGE.
A3: https://github.com/dcajasn/Riskfolio-Lib
B4: Portfolio 1
A5: Profitability and Other Inputs
A6: Total Days in DataBase | B6: =365 -> 0
A7: Mean Return (1) | B7: =AVERAGE(Portfolios!$B$2:$B$252) * 252 -> 0
A8: Compound Annual Growth Rate (CAGR) | B8: {=PRODUCT(1 + Portfolios!$B$2:$B$252)^(252/365)-1} -> 0
A9: Minimum Acceptable Return (MAR) (1) | B9: =0.00015873015873015873 -> 0
A10: Alpha | B10: =0.05 -> 0
A12: Risk Measures based on Returns
A13: Standard Deviation (2) | B13: =STDEV(Portfolios!$B$2:$B$252) * SQRT(252) -> 0
A14: Mean Absolute Deviation (MAD) (2) | B14: =AVERAGE(Absdev!$B$2:$B$252) * SQRT(252) -> 0
A15: Semi Standard Deviation (2) | B15: =SQRT(SUMSQ(devBelowMean!$B$2:$B$252)/(COUNT(devBelowMean!$B$2:$B$252) - 1)) * SQRT(252) -> 0
A16: First Lower Partial Moment (FLPM) (2) | B16: =AVERAGE(devBelowTarget!$B$2:$B$252) * SQRT(252) -> 0
A17: Second Lower Partial Moment (SLPM) (2) | B17: =SQRT(SUMSQ(devBelowTarget!$B$2:$B$252)/(COUNT(devBelowTarget!$B$2:$B$252) - 1)) * SQRT(252) -> 0
A18: Value at Risk (VaR) (2) | B18: =-SMALL(Portfolios!$B$2:$B$252,ROUNDUP(COUNT(Portfolios!$B$2:$B$252)*B10,0)) * SQRT(252) -> 0
A19: Conditional Value at Risk (CVaR) (2) | B19: =-((SUMIF(Portfolios!$B$2:$B$252,"<="&(-B18/SQRT(252)),Portfolios!$B$2:$B$252)-ROUNDUP(COUNT(Portfolios!$B$2:$B$252)*B10,0)*(-B18/SQRT(252)))/(COUNT(Portfolios!$B$2:$B$252)*B10)-B18/SQRT(252)) * SQRT(252) -> 0
A20: Entropic Value at Risk (EVaR) (2) | B20: =0.0206105660852088 * SQRT(252) -> 0
A21: Worst Realization (2) | B21: =-MIN(Portfolios!$B$2:$B$252) * SQRT(252) -> 0
A22: Skewness | B22: =SKEW(Portfolios!$B$2:$B$252) -> 0
A23: Kurtosis | B23: =KURT(Portfolios!$B$2:$B$252) -> 0
A25: Risk Measures based on Drawdowns (3)
A26: Ulcer Index (UCI) | B26: =SQRT(SUMSQ(Drawdown!$B$2:$B$252)/COUNT(Drawdown!$B$2:$B$252)) -> 0
A27: Average Drawdown (ADD) | B27: =AVERAGE(Drawdown!$B$2:$B$252) -> 0
A28: Drawdown at Risk (DaR) | B28: =+LARGE(Drawdown!$B$2:$B$252,ROUNDUP(COUNT(Drawdown!$B$2:$B$252)*B10,0)) -> 0
A29: Conditional Drawdown at Risk (CDaR) | B29: =((SUMIF(Drawdown!$B$2:$B$252,">="&LARGE(Drawdown!$B$2:$B$252,ROUNDUP(COUNT(Drawdown!$B$2:$B$252)*B10,0)),Drawdown!$B$2:$B$252)-ROUNDUP(COUNT(Drawdown!$B$2:$B$252)*B10,0)*LARGE(Drawdown!$B$2:$B$252,ROUNDUP(COUNT(Drawdown!$B$2:$B$252)*B10,0)))/(COUNT(Drawdown!$B$2:$B$252)*B10)+LARGE(Drawdown!$B$2:$B$252,ROUNDUP(COUNT(Drawdown!$B$2:$B$252)*B10,0))) -> 0
A30: Entropic Drawdown at Risk (CDaR) | B30: =0.056312122409362675 -> 0
A31: Max Drawdown (MDD) | B31: =MAX(Drawdown!$B$2:$B$252) -> 0
A32: (1) Annualized, multiplied by 252
A33: (2) Annualized, multiplied by √252
A34: (3) Based on uncompounded cumulated returns
B37: Portfolio 1
A38: FIDU | B38: 1

Sheet Returns
A1: Date | B1: FIDU
A2: 45239 | B2: -0.0011155533
A3: 45240 | B3: 0.014330953
A4: 45243 | B4: 0.00073394231
A5: 45244 | B5: 0.025485844
A6: 45245 | B6: 0.0016091659
A7: 45246 | B7: -0.0016065807
A8: 45247 | B8: 0.0066154059
A9: 45250 | B9: 0.0030196138
A10: 45251 | B10: -0.0014167451
A11: 45252 | B11: 0.0030147254
A12: 45254 | B12: 0.0031825528
A13: 45257 | B13: -0.0047585817
... A252: 45603 | B252: -0.0034286829

Sheet Portfolios
A1: Date | B1: Portfolio 1
A2: =Returns!A2 -> 0 | B2: {=MMULT(Returns!B2,Resume!$B$38)} -> 0
A3: =Returns!A3 -> 0 | B3: {=MMULT(Returns!B3,Resume!$B$38)} -> 0
A4: =Returns!A4 -> 0 | B4: {=MMULT(Returns!B4,Resume!$B$38)} -> 0
A5: =Returns!A5 -> 0 | B5: {=MMULT(Returns!B5,Resume!$B$38)} -> 0
A6: =Returns!A6 -> 0 | B6: {=MMULT(Returns!B6,Resume!$B$38)} -> 0
A7: =Returns!A7 -> 0 | B7: {=MMULT(Returns!B7,Resume!$B$38)} -> 0
A8: =Returns!A8 -> 0 | B8: {=MMULT(Returns!B8,Resume!$B$38)} -> 0
A9: =Returns!A9 -> 0 | B9: {=MMULT(Returns!B9,Resume!$B$38)} -> 0
A10: =Returns!A10 -> 0 | B10: {=MMULT(Returns!B10,Resume!$B$38)} -> 0
A11: =Returns!A11 -> 0 | B11: {=MMULT(Returns!B11,Resume!$B$38)} -> 0
A12: =Returns!A12 -> 0 | B12: {=MMULT(Returns!B12,Resume!$B$38)} -> 0
A13: =Returns!A13 -> 0 | B13: {=MMULT(Returns!B13,Resume!$B$38)} -> 0
... A252: =Returns!A252 -> 0 | B252: {=MMULT(Returns!B252,Resume!$B$38)} -> 0

Sheet Absdev
A1: Date | B1: Portfolio 1
A2: =Returns!A2 -> 0 | B2: =ABS(Portfolios!B2-AVERAGE(Portfolios!$B$2:$B$252)) -> 0
A3: =Returns!A3 -> 0 | B3: =ABS(Portfolios!B3-AVERAGE(Portfolios!$B$2:$B$252)) -> 0
A4: =Returns!A4 -> 0 | B4: =ABS(Portfolios!B4-AVERAGE(Portfolios!$B$2:$B$252)) -> 0
A5: =Returns!A5 -> 0 | B5: =ABS(Portfolios!B5-AVERAGE(Portfolios!$B$2:$B$252)) -> 0
A6: =Returns!A6 -> 0 | B6: =ABS(Portfolios!B6-AVERAGE(Portfolios!$B$2:$B$252)) -> 0
A7: =Returns!A7 -> 0 | B7: =ABS(Portfolios!B7-AVERAGE(Portfolios!$B$2:$B$252)) -> 0
A8: =Returns!A8 -> 0 | B8: =ABS(Portfolios!B8-AVERAGE(Portfolios!$B$2:$B$252)) -> 0
A9: =Returns!A9 -> 0 | B9: =ABS(Portfolios!B9-AVERAGE(Portfolios!$B$2:$B$252)) -> 0
A10: =Returns!A10 -> 0 | B10: =ABS(Portfolios!B10-AVERAGE(Portfolios!$B$2:$B$252)) -> 0
A11: =Returns!A11 -> 0 | B11: =ABS(Portfolios!B11-AVERAGE(Portfolios!$B$2:$B$252)) -> 0
A12: =Returns!A12 -> 0 | B12: =ABS(Portfolios!B12-AVERAGE(Portfolios!$B$2:$B$252)) -> 0
A13: =Returns!A13 -> 0 | B13: =ABS(Portfolios!B13-AVERAGE(Portfolios!$B$2:$B$252)) -> 0
... A252: =Returns!A252 -> 0 | B252: =ABS(Portfolios!B252-AVERAGE(Portfolios!$B$2:$B$252)) -> 0

Sheet CumRet
A1: Date | B1: Portfolio 1
A2: =Returns!A2 -> 0 | B2: =SUM(Portfolios!$B$2) -> 0
A3: =Returns!A3 -> 0 | B3: =SUM(Portfolios!$B$2:$B$3) -> 0
A4: =Returns!A4 -> 0 | B4: =SUM(Portfolios!$B$2:$B$4) -> 0
A5: =Returns!A5 -> 0 | B5: =SUM(Portfolios!$B$2:$B$5) -> 0
A6: =Returns!A6 -> 0 | B6: =SUM(Portfolios!$B$2:$B$6) -> 0
A7: =Returns!A7 -> 0 | B7: =SUM(Portfolios!$B$2:$B$7) -> 0
A8: =Returns!A8 -> 0 | B8: =SUM(Portfolios!$B$2:$B$8) -> 0
A9: =Returns!A9 -> 0 | B9: =SUM(Portfolios!$B$2:$B$9) -> 0
A10: =Returns!A10 -> 0 | B10: =SUM(Portfolios!$B$2:$B$10) -> 0
A11: =Returns!A11 -> 0 | B11: =SUM(Portfolios!$B$2:$B$11) -> 0
A12: =Returns!A12 -> 0 | B12: =SUM(Portfolios!$B$2:$B$12) -> 0
A13: =Returns!A13 -> 0 | B13: =SUM(Portfolios!$B$2:$B$13) -> 0
A14: =Returns!A14 -> 0 | B14: =SUM(Portfolios!$B$2:$B$14) -> 0
A15: =Returns!A15 -> 0 | B15: =SUM(Portfolios!$B$2:$B$15) -> 0
A16: =Returns!A16 -> 0 | B16: =SUM(Portfolios!$B$2:$B$16) -> 0
A17: =Returns!A17 -> 0 | B17: =SUM(Portfolios!$B$2:$B$17) -> 0
A18: =Returns!A18 -> 0 | B18: =SUM(Portfolios!$B$2:$B$18) -> 0
A19: =Returns!A19 -> 0 | B19: =SUM(Portfolios!$B$2:$B$19) -> 0
A20: =Returns!A20 -> 0 | B20: =SUM(Portfolios!$B$2:$B$20) -> 0
A21: =Returns!A21 -> 0 | B21: =SUM(Portfolios!$B$2:$B$21) -> 0
A22: =Returns!A22 -> 0 | B22: =SUM(Portfolios!$B$2:$B$22) -> 0
A23: =Returns!A23 -> 0 | B23: =SUM(Portfolios!$B$2:$B$23) -> 0
A24: =Returns!A24 -> 0 | B24: =SUM(Portfolios!$B$2:$B$24) -> 0
A25: =Returns!A25 -> 0 | B25: =SUM(Portfolios!$B$2:$B$25) -> 0
A26: =Returns!A26 -> 0 | B26: =SUM(Portfolios!$B$2:$B$26) -> 0
A27: =Returns!A27 -> 0 | B27: =SUM(Portfolios!$B$2:$B$27) -> 0
A28: =Returns!A28 -> 0 | B28: =SUM(Portfolios!$B$2:$B$28) -> 0
A29: =Returns!A29 -> 0 | B29: =SUM(Portfolios!$B$2:$B$29) -> 0
A30: =Returns!A30 -> 0 | B30: =SUM(Portfolios!$B$2:$B$30) -> 0
A31: =Returns!A31 -> 0 | B31: =SUM(Portfolios!$B$2:$B$31) -> 0
A32: =Returns!A32 -> 0 | B32: =SUM(Portfolios!$B$2:$B$32) -> 0
A33: =Returns!A33 -> 0 | B33: =SUM(Portfolios!$B$2:$B$33) -> 0
A34: =Returns!A34 -> 0 | B34: =SUM(Portfolios!$B$2:$B$34) -> 0
A35: =Returns!A35 -> 0 | B35: =SUM(Portfolios!$B$2:$B$35) -> 0
A36: =Returns!A36 -> 0 | B36: =SUM(Portfolios!$B$2:$B$36) -> 0
A37: =Returns!A37 -> 0 | B37: =SUM(Portfolios!$B$2:$B$37) -> 0
A38: =Returns!A38 -> 0 | B38: =SUM(Portfolios!$B$2:$B$38) -> 0
A39: =Returns!A39 -> 0 | B39: =SUM(Portfolios!$B$2:$B$39) -> 0
A40: =Returns!A40 -> 0 | B40: =SUM(Portfolios!$B$2:$B$40) -> 0
...

Sheet Drawdown
A1: Date | B1: Portfolio 1
A2: =Returns!A2 -> 0 | B2: =MAX(CumRet!$B$2)-CumRet!B2 -> 0
A3: =Returns!A3 -> 0 | B3: =MAX(CumRet!$B$2:$B$3)-CumRet!B3 -> 0
A4: =Returns!A4 -> 0 | B4: =MAX(CumRet!$B$2:$B$4)-CumRet!B4 -> 0
A5: =Returns!A5 -> 0 | B5: =MAX(CumRet!$B$2:$B$5)-CumRet!B5 -> 0
A6: =Returns!A6 -> 0 | B6: =MAX(CumRet!$B$2:$B$6)-CumRet!B6 -> 0
A7: =Returns!A7 -> 0 | B7: =MAX(CumRet!$B$2:$B$7)-CumRet!B7 -> 0
A8: =Returns!A8 -> 0 | B8: =MAX(CumRet!$B$2:$B$8)-CumRet!B8 -> 0
A9: =Returns!A9 -> 0 | B9: =MAX(CumRet!$B$2:$B$9)-CumRet!B9 -> 0
A10: =Returns!A10 -> 0 | B10: =MAX(CumRet!$B$2:$B$10)-CumRet!B10 -> 0
A11: =Returns!A11 -> 0 | B11: =MAX(CumRet!$B$2:$B$11)-CumRet!B11 -> 0
A12: =Returns!A12 -> 0 | B12: =MAX(CumRet!$B$2:$B$12)-CumRet!B12 -> 0
A13: =Returns!A13 -> 0 | B13: =MAX(CumRet!$B$2:$B$13)-CumRet!B13 -> 0
A14: =Returns!A14 -> 0 | B14: =MAX(CumRet!$B$2:$B$14)-CumRet!B14 -> 0
A15: =Returns!A15 -> 0 | B15: =MAX(CumRet!$B$2:$B$15)-CumRet!B15 -> 0
A16: =Returns!A16 -> 0 | B16: =MAX(CumRet!$B$2:$B$16)-CumRet!B16 -> 0
A17: =Returns!A17 -> 0 | B17: =MAX(CumRet!$B$2:$B$17)-CumRet!B17 -> 0
A18: =Returns!A18 -> 0 | B18: =MAX(CumRet!$B$2:$B$18)-CumRet!B18 -> 0
A19: =Returns!A19 -> 0 | B19: =MAX(CumRet!$B$2:$B$19)-CumRet!B19 -> 0
A20: =Returns!A20 -> 0 | B20: =MAX(CumRet!$B$2:$B$20)-CumRet!B20 -> 0
A21: =Returns!A21 -> 0 | B21: =MAX(CumRet!$B$2:$B$21)-CumRet!B21 -> 0
A22: =Returns!A22 -> 0 | B22: =MAX(CumRet!$B$2:$B$22)-CumRet!B22 -> 0
A23: =Returns!A23 -> 0 | B23: =MAX(CumRet!$B$2:$B$23)-CumRet!B23 -> 0
A24: =Returns!A24 -> 0 | B24: =MAX(CumRet!$B$2:$B$24)-CumRet!B24 -> 0
A25: =Returns!A25 -> 0 | B25: =MAX(CumRet!$B$2:$B$25)-CumRet!B25 -> 0
A26: =Returns!A26 -> 0 | B26: =MAX(CumRet!$B$2:$B$26)-CumRet!B26 -> 0
A27: =Returns!A27 -> 0 | B27: =MAX(CumRet!$B$2:$B$27)-CumRet!B27 -> 0
A28: =Returns!A28 -> 0 | B28: =MAX(CumRet!$B$2:$B$28)-CumRet!B28 -> 0
A29: =Returns!A29 -> 0 | B29: =MAX(CumRet!$B$2:$B$29)-CumRet!B29 -> 0
A30: =Returns!A30 -> 0 | B30: =MAX(CumRet!$B$2:$B$30)-CumRet!B30 -> 0
A31: =Returns!A31 -> 0 | B31: =MAX(CumRet!$B$2:$B$31)-CumRet!B31 -> 0
A32: =Returns!A32 -> 0 | B32: =MAX(CumRet!$B$2:$B$32)-CumRet!B32 -> 0
A33: =Returns!A33 -> 0 | B33: =MAX(CumRet!$B$2:$B$33)-CumRet!B33 -> 0
A34: =Returns!A34 -> 0 | B34: =MAX(CumRet!$B$2:$B$34)-CumRet!B34 -> 0
A35: =Returns!A35 -> 0 | B35: =MAX(CumRet!$B$2:$B$35)-CumRet!B35 -> 0
A36: =Returns!A36 -> 0 | B36: =MAX(CumRet!$B$2:$B$36)-CumRet!B36 -> 0
A37: =Returns!A37 -> 0 | B37: =MAX(CumRet!$B$2:$B$37)-CumRet!B37 -> 0
A38: =Returns!A38 -> 0 | B38: =MAX(CumRet!$B$2:$B$38)-CumRet!B38 -> 0
A39: =Returns!A39 -> 0 | B39: =MAX(CumRet!$B$2:$B$39)-CumRet!B39 -> 0
A40: =Returns!A40 -> 0 | B40: =MAX(CumRet!$B$2:$B$40)-CumRet!B40 -> 0
...

Sheet devBelowTarget
A1: Date | B1: Portfolio 1
A2: =Returns!A2 -> 0 | B2: =MAX(Resume!B9/ 252-Portfolios!B2, 0) -> 0
A3: =Returns!A3 -> 0 | B3: =MAX(Resume!B9/ 252-Portfolios!B3, 0) -> 0
A4: =Returns!A4 -> 0 | B4: =MAX(Resume!B9/ 252-Portfolios!B4, 0) -> 0
A5: =Returns!A5 -> 0 | B5: =MAX(Resume!B9/ 252-Portfolios!B5, 0) -> 0
A6: =Returns!A6 -> 0 | B6: =MAX(Resume!B9/ 252-Portfolios!B6, 0) -> 0
A7: =Returns!A7 -> 0 | B7: =MAX(Resume!B9/ 252-Portfolios!B7, 0) -> 0
A8: =Returns!A8 -> 0 | B8: =MAX(Resume!B9/ 252-Portfolios!B8, 0) -> 0
A9: =Returns!A9 -> 0 | B9: =MAX(Resume!B9/ 252-Portfolios!B9, 0) -> 0
A10: =Returns!A10 -> 0 | B10: =MAX(Resume!B9/ 252-Portfolios!B10, 0) -> 0
A11: =Returns!A11 -> 0 | B11: =MAX(Resume!B9/ 252-Portfolios!B11, 0) -> 0
A12: =Returns!A12 -> 0 | B12: =MAX(Resume!B9/ 252-Portfolios!B12, 0) -> 0
A13: =Returns!A13 -> 0 | B13: =MAX(Resume!B9/ 252-Portfolios!B13, 0) -> 0
A14: =Returns!A14 -> 0 | B14: =MAX(Resume!B9/ 252-Portfolios!B14, 0) -> 0
A15: =Returns!A15 -> 0 | B15: =MAX(Resume!B9/ 252-Portfolios!B15, 0) -> 0
A16: =Returns!A16 -> 0 | B16: =MAX(Resume!B9/ 252-Portfolios!B16, 0) -> 0
A17: =Returns!A17 -> 0 | B17: =MAX(Resume!B9/ 252-Portfolios!B17, 0) -> 0
A18: =Returns!A18 -> 0 | B18: =MAX(Resume!B9/ 252-Portfolios!B18, 0) -> 0
A19: =Returns!A19 -> 0 | B19: =MAX(Resume!B9/ 252-Portfolios!B19, 0) -> 0
A20: =Returns!A20 -> 0 | B20: =MAX(Resume!B9/ 252-Portfolios!B20, 0) -> 0
A21: =Returns!A21 -> 0 | B21: =MAX(Resume!B9/ 252-Portfolios!B21, 0) -> 0
A22: =Returns!A22 -> 0 | B22: =MAX(Resume!B9/ 252-Portfolios!B22, 0) -> 0
A23: =Returns!A23 -> 0 | B23: =MAX(Resume!B9/ 252-Portfolios!B23, 0) -> 0
A24: =Returns!A24 -> 0 | B24: =MAX(Resume!B9/ 252-Portfolios!B24, 0) -> 0
A25: =Returns!A25 -> 0 | B25: =MAX(Resume!B9/ 252-Portfolios!B25, 0) -> 0
A26: =Returns!A26 -> 0 | B26: =MAX(Resume!B9/ 252-Portfolios!B26, 0) -> 0
A27: =Returns!A27 -> 0 | B27: =MAX(Resume!B9/ 252-Portfolios!B27, 0) -> 0
A28: =Returns!A28 -> 0 | B28: =MAX(Resume!B9/ 252-Portfolios!B28, 0) -> 0
A29: =Returns!A29 -> 0 | B29: =MAX(Resume!B9/ 252-Portfolios!B29, 0) -> 0
A30: =Returns!A30 -> 0 | B30: =MAX(Resume!B9/ 252-Portfolios!B30, 0) -> 0
A31: =Returns!A31 -> 0 | B31: =MAX(Resume!B9/ 252-Portfolios!B31, 0) -> 0
A32: =Returns!A32 -> 0 | B32: =MAX(Resume!B9/ 252-Portfolios!B32, 0) -> 0
A33: =Returns!A33 -> 0 | B33: =MAX(Resume!B9/ 252-Portfolios!B33, 0) -> 0
A34: =Returns!A34 -> 0 | B34: =MAX(Resume!B9/ 252-Portfolios!B34, 0) -> 0
A35: =Returns!A35 -> 0 | B35: =MAX(Resume!B9/ 252-Portfolios!B35, 0) -> 0
A36: =Returns!A36 -> 0 | B36: =MAX(Resume!B9/ 252-Portfolios!B36, 0) -> 0
A37: =Returns!A37 -> 0 | B37: =MAX(Resume!B9/ 252-Portfolios!B37, 0) -> 0
A38: =Returns!A38 -> 0 | B38: =MAX(Resume!B9/ 252-Portfolios!B38, 0) -> 0
A39: =Returns!A39 -> 0 | B39: =MAX(Resume!B9/ 252-Portfolios!B39, 0) -> 0
A40: =Returns!A40 -> 0 | B40: =MAX(Resume!B9/ 252-Portfolios!B40, 0) -> 0
...

Sheet devBelowMean
A1: Date | B1: Portfolio 1
A2: =Returns!A2 -> 0 | B2: =MAX(AVERAGE(Portfolios!$B$2:$B$252)-Portfolios!B2, 0) -> 0
A3: =Returns!A3 -> 0 | B3: =MAX(AVERAGE(Portfolios!$B$2:$B$252)-Portfolios!B3, 0) -> 0
A4: =Returns!A4 -> 0 | B4: =MAX(AVERAGE(Portfolios!$B$2:$B$252)-Portfolios!B4, 0) -> 0
A5: =Returns!A5 -> 0 | B5: =MAX(AVERAGE(Portfolios!$B$2:$B$252)-Portfolios!B5, 0) -> 0
A6: =Returns!A6 -> 0 | B6: =MAX(AVERAGE(Portfolios!$B$2:$B$252)-Portfolios!B6, 0) -> 0
A7: =Returns!A7 -> 0 | B7: =MAX(AVERAGE(Portfolios!$B$2:$B$252)-Portfolios!B7, 0) -> 0
A8: =Returns!A8 -> 0 | B8: =MAX(AVERAGE(Portfolios!$B$2:$B$252)-Portfolios!B8, 0) -> 0
A9: =Returns!A9 -> 0 | B9: =MAX(AVERAGE(Portfolios!$B$2:$B$252)-Portfolios!B9, 0) -> 0
A10: =Returns!A10 -> 0 | B10: =MAX(AVERAGE(Portfolios!$B$2:$B$252)-Portfolios!B10, 0) -> 0
A11: =Returns!A11 -> 0 | B11: =MAX(AVERAGE(Portfolios!$B$2:$B$252)-Portfolios!B11, 0) -> 0
A12: =Returns!A12 -> 0 | B12: =MAX(AVERAGE(Portfolios!$B$2:$B$252)-Portfolios!B12, 0) -> 0
A13: =Returns!A13 -> 0 | B13: =MAX(AVERAGE(Portfolios!$B$2:$B$252)-Portfolios!B13, 0) -> 0
... A252: =Returns!A252 -> 0 | B252: =MAX(AVERAGE(Portfolios!$B$2:$B$252)-Portfolios!B252, 0) -> 0
